Workbook

Sheet Redemption List
A1: 0 | B1: BS Email? | C1: Voucher Delivery Status | D1: Working days passed | E1: Working Days Max | F1: Date of Redemption | G1: Email | H1: Full name | I1: Employee ID | J1: Number | K1: Reward Name | L1: BDT Value+ | M1: Selected Reward Option | N1: BS Communication | O1: Voucher in proccess | P1: Delivery Status Due = 0 | Q1: Voucher Type | R1: Date ( For Late Deivery) | S1: Remarks | T1: @
A2: 1 | D2: 3 | E2: 7 | F2: 46149.536 | G2: kmislam@square.org | H2: K. M. Nazmul Islam | I2: 12442 | J2: 1862401843 | K2: Daraz | L2: 2000 | M2: 2000 Voucher
A3: 2 | B3: Done | C3: Deliverd(10.05.26) | D3: Done | E3: 7 | F3: 46147.399 | G3: waislam@square.org | H3: Md. Wahidul Islam | I3: 5096 | J3: 1814444620 | K3: Gadget & Gear | L3: 20000 | M3: 20000 Voucher | P3: Complete
A4: 3 | B4: Done | C4: Deliverd(10.05.26) | D4: Done | E4: 7 | F4: 46145.138 | G4: soksaha@square.org | H4: Soumitra Kumar Saha | I4: 9816 | J4: 1826662611 | K4: Daraz | L4: 1000 | M4: 1000 Voucher | P4: Complete
A5: 4 | B5: Done | C5: Deliverd(10.05.26) | D5: Done | E5: 7 | F5: 46145.137 | G5: soksaha@square.org | H5: Soumitra Kumar Saha | I5: 9816 | J5: 1826662611 | K5: Daraz | L5: 500 | M5: 500 Voucher | P5: Complete
A6: 5 | B6: Done | C6: Deliverd(10.05.26) | D6: Done | E6: 7 | F6: 46145.088 | G6: mdahossain@square.org | H6: Md. Ali Asgar Hossain | I6: 905 | J6: 1811310618 | K6: Aarong | L6: 3000 | M6: 3000 Voucher | P6: Complete
A7: 6 | B7: Done | C7: Deliverd(10.05.26) | D7: Done | E7: 7 | F7: 46145.085 | G7: mdahossain@square.org | H7: Md. Ali Asgar Hossain | I7: 905 | J7: 1811310618 | K7: Bata | L7: 3000 | M7: 3000 Voucher | P7: Complete
A8: 7 | B8: Done | C8: Deliverd(10.05.26) | D8: Done | E8: 7 | F8: 46145.085 | G8: mdahossain@square.org | H8: Md. Ali Asgar Hossain | I8: 905 | J8: 1811310618 | K8: Aarong | L8: 5000 | M8: 5000 Voucher | P8: Complete
A9: 8 | B9: Done | C9: Deliverd(07.05.26) | D9: Done | E9: 7 | F9: 46145.065 | G9: sohiduzzaman@square.org | H9: Syed Ohiduzzaman | I9: 899 | J9: 1812311170 | K9: Apple Gadget | L9: 5000 | M9: 5000 Voucher | P9: Complete
A10: 9 | B10: Done | C10: Deliverd(07.05.26) | D10: Done | E10: 7 | F10: 46145.065 | G10: sohiduzzaman@square.org | H10: Syed Ohiduzzaman | I10: 899 | J10: 1812311170 | K10: Apple Gadget | L10: 5000 | M10: 5000 Voucher | P10: Complete
A11: 10 | B11: Done | C11: Deliverd(07.05.26) | D11: Done | E11: 7 | F11: 46145.051 | G11: sohiduzzaman@square.org | H11: Syed Ohiduzzaman | I11: 899 | J11: 1812311170 | K11: Apple Gadget | L11: 5000 | M11: 5000 Voucher | P11: Complete
A12: 11 | B12: Done | C12: Deliverd(07.05.26) | D12: Done | E12: 7 | F12: 46145.051 | G12: sohiduzzaman@square.org | H12: Syed Ohiduzzaman | I12: 899 | J12: 1812311170 | K12: Apple Gadget | L12: 5000 | M12: 5000 Voucher | P12: Complete
A13: 12 | B13: Done | C13: Deliverd(07.05.26) | D13: Done | E13: 7 | F13: 46145.41 | G13: fakislam@square.org | H13: Md. Fakhrul Islam | I13: 11804 | J13: 1862400903 | K13: Apple Gadget | L13: 5000 | M13: 5000 Voucher | P13: Complete
A14: 13 | B14: Done | C14: Deliverd(07.05.26) | D14: Done | E14: 7 | F14: 46145.41 | G14: fakislam@square.org | H14: Md. Fakhrul Islam | I14: 11804 | J14: 1862400903 | K14: Apple Gadget | L14: 5000 | M14: 5000 Voucher | P14: Complete
... A35: 34 | B35: Done | C35: Deliverd(04.05.26) | D35: Done | E35: 7 | F35: 46138.516 | G35: refayat.ahmed@square.org | H35: Refayat Ahmed | I35: 13076 | J35: 1862424731 | K35: Daraz | L35: 3000 | M35: 3000 Voucher | P35: Complete
A36: 35 | B36: Done | C36: Deliverd(26.04.26) | D36: Done | E36: 5 | F36: 46138.509 | G36: emdadul.haque@square.org | H36: Md. Emdadul Haque | I36: 13059 | J36: 1862424715 | K36: Star Cineplex (Sony Square) | L36: 450 | M36: 450 Voucher | AD36: 1
A37: 36 | B37: Done | C37: Deliverd(05.05.26) | D37: Done | E37: 7 | F37: 46137.153 | G37: Krahman@square.org | H37: Kazi Maksudur Rahman | I37: 334 | J37: 1811310604 | K37: Aarong | L37: 2000 | M37: 2000 Vocuher | P37: Complete
A38: 37 | B38: Done | C38: Deliverd(03.05.26 | D38: Done | E38: 7 | F38: 46136.504 | G38: mohalam@square.org | H38: Mohammad Sabbir Alam | I38: 675 | J38: 1811310958 | K38: Apple Gadget | L38: 5000 | M38: 5000 Voucher | P38: Complete
A39: 38 | B39: Done | C39: Deliverd(03.05.26 | D39: Done | E39: 7 | F39: 46136.504 | G39: mohalam@square.org | H39: Mohammad Sabbir Alam | I39: 675 | J39: 1811310958 | K39: Apple Gadget | L39: 5000 | M39: 5000 Voucher | P39: Complete
A40: 39 | B40: Done | C40: Deliverd(03.05.26 | D40: Done | E40: 7 | F40: 46136.504 | G40: mohalam@square.org | H40: Mohammad Sabbir Alam | I40: 675 | J40: 1811310958 | K40: Apple Gadget | L40: 5000 | M40: 5000 Voucher | P40: Complete
A41: 40 | B41: Done | C41: Deliverd(03.05.26 | D41: Done | E41: 7 | F41: 46136.504 | G41: mohalam@square.org | H41: Mohammad Sabbir Alam | I41: 675 | J41: 1811310958 | K41: Apple Gadget | L41: 5000 | M41: 5000 Voucher | P41: Complete
A42: 41 | B42: Done | C42: Deliverd(04.05.26) | D42: Done | E42: 7 | F42: 46135.053 | G42: abdur.yead@square.org | H42: Abdur Rafeu Yead | I42: 14396 | J42: 1862425207 | K42: Daraz | L42: 2000 | M42: 2000 Vocuher | P42: Complete
A43: 42 | B43: Done | C43: Deliverd(22.04.26) | D43: Done | E43: 7 | F43: 46133.094 | G43: md.hasan@square.org | H43: Md Mahmudul Hasan | I43: 13351 | J43: 1862424991 | K43: Apex | L43: 2500 | M43: 2500 Voucher | AD43: 1
A44: 43 | B44: Done | C44: Deliverd(23.04.26) | D44: Done | E44: 7 | F44: 46133.393 | G44: zansar@square.org | H44: Md. Zubair Ansar | I44: 9215 | J44: 1824400969 | K44: Gadget & Gear | L44: 15000 | M44: 15000 Voucher | AD44: 1
A45: 44 | B45: Done | C45: Deliverd(22.04.26) | D45: Done | E45: 7 | F45: 46132.156 | G45: kazi.mostafa@square.org | H45: Kazi Farhan Mostafa | I45: 14996 | J45: 1801455269 | K45: Daraz | L45: 500 | M45: 500 Voucher | AD45: 1
A46: 45 | B46: Done | C46: Deliverd(22.04.26) | D46: Done | E46: 7 | F46: 46132.115 | G46: ezaz.ahmed@square.org | H46: Sk Ezaz Ahmed | I46: 13401 | J46: 1862425106 | K46: Daraz | L46: 2000 | M46: 2000 Vocuher | AD46: 1
A47: 46 | B47: Done | C47: Deliverd(26.04.26) | D47: Done | E47: 5 | F47: 46132.425 | G47: emdadul.haque@square.org | H47: Md. Emdadul Haque | I47: 13059 | J47: 1862424715 | K47: Star Cineplex (Sony Square) | L47: 450 | M47: 450 Voucher | AD47: 1
A48: 47 | B48: Done | C48: Deliverd(26.04.26) | D48: Done | E48: 5 | F48: 46132.425 | G48: emdadul.haque@square.org | H48: Md. Emdadul Haque | I48: 13059 | J48: 1862424715 | K48: Star Cineplex (Sony Square) | L48: 450 | M48: 450 Voucher | AD48: 1
A49: 48 | B49: Done | C49: Deliverd(23.04.26) | D49: Done | E49: 7 | F49: 46132.418 | G49: mashaduzzaman@square.org | H49: Md. Ashaduzzaman | I49: 9529 | J49: 1826662318 | K49: Gadget & Gear | L49: 1000 | M49: 1000 Voucher | AD49: 1
A50: 49 | B50: Done | C50: Deliverd(23.04.26) | D50: Done | E50: 7 | F50: 46131.189 | G50: anika.tabassum@square.org | H50: Anika Tabassum | I50: 14422 | J50: 1801455148 | K50: Gadget & Gear | L50: 2500 | M50: 2500 Voucher | AD50: 1
A51: 50 | B51: Done | C51: Deliverd(22.04.26) | D51: Done | E51: 7 | F51: 46130.433 | G51: saiazam@square.org | H51: Md. Saiful Azam | I51: 9108 | J51: 1824400853 | K51: Daraz | L51: 1500 | M51: 1500 Vocuher | AD51: 1
A52: 51 | B52: Done | C52: Deliverd(22.04.26) | D52: Done | E52: 7 | F52: 46129.536 | G52: moshiur.aunik@square.org | H52: Md Moshiur Rahman Aunik | I52: 13468 | J52: 1862425250 | K52: Daraz | L52: 1000 | M52: 1000 Voucher | AD52: 1
A53: 52 | B53: Done | C53: Deliverd(22.04.26) | D53: Done | E53: 7 | F53: 46128.085 | G53: mmaniruzzaman@square.org | H53: Md Maniruzzaman | I53: 12685 | J53: 1862424320 | K53: Daraz | L53: 1000 | M53: 1000 Voucher | AD53: 1
A54: 53 | B54: Done | C54: Deliverd(23.04.26) | D54: Done | E54: 5 | F54: 46128.061 | G54: mnazmulislam@square.org | H54: Md. Nazmul Islam | I54: 12623 | J54: 1862424259 | K54: Foodpanda | L54: 10000 | M54: 10000 Voucher | AD54: 1
... A92: 91 | B92: Done | C92: Delivered (16.04.26) | D92: Done | E92: 5 | F92: 46112.169 | G92: fahad.bappy@square.org | H92: Fahad Hossain Bappy | I92: 13684 | J92: 1862425515 | K92: Star Cineplex (Sony Square) | L92: 500 | M92: 500 Voucher | AD92: 1
A93: 92 | B93: Done | C93: Delivered (31.03.26) | D93: Done | E93: 5 | F93: 46112.088 | G93: ramisa.priota@square.org | H93: Ramisa Mahmud Priota | I93: 15160 | J93: 1801455310 | K93: Gloria Jeans | L93: 1000 | M93: 1000 Voucher | S93: Bill Feb-Mar 2026 | AD93: 1
A94: 93 | B94: Done | C94: Deliverd(23.04.26) | D94: Done | E94: 5 | F94: 46112.48 | G94: KMustafa@square.org | H94: Kallol Mustafa | I94: 695 | J94: 1811310103 | K94: Star Cineplex (Basundhara City) | L94: 500 | M94: 500 Voucher | AD94: 1
A95: 94 | B95: Done | C95: Deliverd(23.04.26) | D95: Done | E95: 5 | F95: 46112.474 | G95: KMustafa@square.org | H95: Kallol Mustafa | I95: 695 | J95: 1811310103 | K95: Star Cineplex (Basundhara City) | L95: 500 | M95: 500 Voucher | AD95: 1
A96: 95 | B96: Done | C96: Delivered (02.04.26) | D96: Done | E96: 7 | F96: 46112.463 | G96: ayhaque@square.org | H96: Md Aynul Haque | I96: 757 | J96: 1811310889 | K96: Daraz | L96: 2000 | M96: 2000 Voucher | AD96: 1
A97: 96 | B97: Done | C97: Delivered (02.04.26) | D97: Done | E97: 7 | F97: 46112.463 | G97: ayhaque@square.org | H97: Md Aynul Haque | I97: 757 | J97: 1811310889 | K97: Daraz | L97: 20000 | M97: 20000 Voucher | AD97: 1
...

Sheet Summery
A1: =IFERROR(__xludf.DUMMYFUNCTION("FILTER('Employee Info'!N1:N7,'Employee Info'!U1:U7="""")"),"") | B1: =IFERROR(__xludf.DUMMYFUNCTION("FILTER('Employee Info'!O1:O19,'Employee Info'!U1:U19="""")"),"") | C1: =IFERROR(__xludf.DUMMYFUNCTION("FILTER('Employee Info'!Q1:Q19,'Employee Info'!U1:U19="""")"),"") | D1: =IFERROR(__xludf.DUMMYFUNCTION("FILTER('Employee Info'!R1:R19,'Employee Info'!U1:U19="""")"),"") | E1: =XLOOKUP(C1,G:G,H:H) -> #NAME? | F1: Timestamp | G1: Voucher Name | H1: Delivery Days | I1: Delivery Days | J1: Voucher Type | Y1: {=UNIQUE('Redemption List'!K:K)} -> #NAME?
E2: =XLOOKUP(C2,G:G,H:H) -> #NAME? | F2: 45915.404 | G2: Daraz | H2: 7 | I2: 5 - 7 days. | J2: Digital | Y2: #NAME?
E3: =XLOOKUP(C3,G:G,H:H) -> #NAME? | G3: Foodpanda | H3: 5 | I3: 3 -5 days. | Y3: #NAME? | Z3: =COUNTIFS('Redemption List'!K:K,Y3,#REF!,"Pending",'Redemption List'!P:P,"Not Yet") -> #REF!
E4: =XLOOKUP(C4,G:G,H:H) -> #NAME? | G4: Gadget & Gear | H4: 7 | I4: 5 - 7 days | Y4: #NAME? | Z4: =COUNTIFS('Redemption List'!K:K,Y4,#REF!,"Pending",'Redemption List'!P:P,"Not Yet") -> #REF!
E5: =XLOOKUP(C5,G:G,H:H) -> #NAME? | G5: Apple Gadget | H5: 7 | I5: 5 - 7 days. | J5: Digital | Y5: #NAME? | Z5: =COUNTIFS('Redemption List'!K:K,Y5,#REF!,"Pending",'Redemption List'!P:P,"Not Yet") -> #REF!
G6: Bread & Beyond | H6: 5 | I6: 3 -5 days. | Y6: #NAME? | Z6: =COUNTIFS('Redemption List'!K:K,Y6,#REF!,"Pending",'Redemption List'!P:P,"Not Yet") -> #REF!
G7: Indulge | H7: 5 | I7: 3 -5 days. | Y7: #NAME? | Z7: =COUNTIFS('Redemption List'!K:K,Y7,#REF!,"Pending",'Redemption List'!P:P,"Not Yet") -> #REF!
A8: Voucher Details Add Link | G8: Farmhouse Burger | H8: 5 | I8: 3 -5 days. | Y8: #NAME? | Z8: =COUNTIFS('Redemption List'!K:K,Y8,#REF!,"Pending",'Redemption List'!P:P,"Not Yet") -> #REF!
G9: Gloria Jeans | H9: 5 | I9: 3 -5 days. | Y9: #NAME? | Z9: =COUNTIFS('Redemption List'!K:K,Y9,#REF!,"Pending",'Redemption List'!P:P,"Not Yet") -> #REF!
A10: https://forms.gle/kQCM8sCneYtPVbK5A | G10: Fish & Co. | H10: 5 | I10: 3 -5 days. | Y10: #NAME? | Z10: =COUNTIFS('Redemption List'!K:K,Y10,#REF!,"Pending",'Redemption List'!P:P,"Not Yet") -> #REF!
G11: Burger king | H11: 5 | I11: 3 -5 days. | Y11: #NAME? | Z11: =COUNTIFS('Redemption List'!K:K,Y11,#REF!,"Pending",'Redemption List'!P:P,"Not Yet") -> #REF!
G12: Bistro- E | H12: 5 | I12: 3 -5 days. | Y12: #NAME? | Z12: =COUNTIFS('Redemption List'!K:K,Y12,#REF!,"Pending",'Redemption List'!P:P,"Not Yet") -> #REF!
G13: Amari Dhaka | H13: 7 | I13: 7 days. | Y13: #NAME? | Z13: =COUNTIFS('Redemption List'!K:K,Y13,#REF!,"Pending",'Redemption List'!P:P,"Not Yet") -> #REF!
G14: Sheraton Dhaka | H14: 7 | I14: 7 days. | Y14: #NAME? | Z14: =COUNTIFS('Redemption List'!K:K,Y14,#REF!,"Pending",'Redemption List'!P:P,"Not Yet") -> #REF!
G15: Redisson Blu Water Garden (Dhaka & Chittagong) | H15: 7 | I15: 7 days. | Z15: =COUNTIFS('Redemption List'!K:K,Y15,#REF!,"Pending",'Redemption List'!P:P,"Not Yet") -> #REF!
G16: Blockbuster Cinema (Jamuna) | H16: 5 | I16: 3 -5 days. | Z16: =COUNTIFS('Redemption List'!K:K,Y16,#REF!,"Pending",'Redemption List'!P:P,"Not Yet") -> #REF!
G17: Star Cineplex (SKS Tower) | H17: 5 | I17: 3 -5 days. | Z17: =COUNTIFS('Redemption List'!K:K,Y17,#REF!,"Pending",'Redemption List'!P:P,"Not Yet") -> #REF!
G18: Star Cineplex (Sony Square) | H18: 5 | I18: 3 -5 days. | Z18: =COUNTIFS('Redemption List'!K:K,Y18,#REF!,"Pending",'Redemption List'!P:P,"Not Yet") -> #REF!
H19: 5 | I19: 3 -5 days. | Z19: =COUNTIFS('Redemption List'!K:K,Y19,#REF!,"Pending",'Redemption List'!P:P,"Not Yet") -> #REF!
G20: Star Cineplex (Basundhara City) | H20: 5 | I20: 3 -5 days. | Z20: =COUNTIFS('Redemption List'!K:K,Y20,#REF!,"Pending",'Redemption List'!P:P,"Not Yet") -> #REF!
G21: Bata | H21: 7 | I21: 5 - 7 days. | Z21: =COUNTIFS('Redemption List'!K:K,Y21,#REF!,"Pending",'Redemption List'!P:P,"Not Yet") -> #REF!
G22: Apex | H22: 7 | I22: 5 - 7 days. | J22: Digital | Z22: =COUNTIFS('Redemption List'!K:K,Y22,#REF!,"Pending",'Redemption List'!P:P,"Not Yet") -> #REF!
G23: Aarong | H23: 7 | I23: 5 - 7 days. | Z23: =COUNTIFS('Redemption List'!K:K,Y23,#REF!,"Pending",'Redemption List'!P:P,"Not Yet") -> #REF!
G24: Artisan | H24: 7 | I24: 5 - 7 days. | Z24: =COUNTIFS('Redemption List'!K:K,Y24,#REF!,"Pending",'Redemption List'!P:P,"Not Yet") -> #REF!
G25: Shwapno | H25: 7 | I25: 5 - 7 days. | Z25: =COUNTIFS('Redemption List'!K:K,Y25,#REF!,"Pending",'Redemption List'!P:P,"Not Yet") -> #REF!
G26: Agora | H26: 7 | I26: 5 - 7 days. | Z26: =COUNTIFS('Redemption List'!K:K,Y26,#REF!,"Pending",'Redemption List'!P:P,"Not Yet") -> #REF!
G27: Persona | H27: 7 | I27: 5 - 7 days. | Z27: =COUNTIFS('Redemption List'!K:K,Y27,#REF!,"Pending",'Redemption List'!P:P,"Not Yet") -> #REF!
G28: Farzana Shakil's Makeover Salon | H28: 7 | I28: 5 - 7 days | Z28: =COUNTIFS('Redemption List'!K:K,Y28,#REF!,"Pending",'Redemption List'!P:P,"Not Yet") -> #REF!
Z29: =COUNTIFS('Redemption List'!K:K,Y29,#REF!,"Pending",'Redemption List'!P:P,"Not Yet") -> #REF!
Z30: =COUNTIFS('Redemption List'!K:K,Y30,#REF!,"Pending",'Redemption List'!P:P,"Not Yet") -> #REF!
Z31: =COUNTIFS('Redemption List'!K:K,Y31,#REF!,"Pending",'Redemption List'!P:P,"Not Yet") -> #REF!
Z32: =COUNTIFS('Redemption List'!K:K,Y32,#REF!,"Pending",'Redemption List'!P:P,"Not Yet") -> #REF!
Z33: =COUNTIFS('Redemption List'!K:K,Y33,#REF!,"Pending",'Redemption List'!P:P,"Not Yet") -> #REF!
Z34: =COUNTIFS('Redemption List'!K:K,Y34,#REF!,"Pending",'Redemption List'!P:P,"Not Yet") -> #REF!
Z35: =COUNTIFS('Redemption List'!K:K,Y35,#REF!,"Pending",'Redemption List'!P:P,"Not Yet") -> #REF!
Z36: =COUNTIFS('Redemption List'!K:K,Y36,#REF!,"Pending",'Redemption List'!P:P,"Not Yet") -> #REF!
Z37: =COUNTIFS('Redemption List'!K:K,Y37,#REF!,"Pending",'Redemption List'!P:P,"Not Yet") -> #REF!
Z38: =COUNTIFS('Redemption List'!K:K,Y38,#REF!,"Pending",'Redemption List'!P:P,"Not Yet") -> #REF!
Z39: =COUNTIFS('Redemption List'!K:K,Y39,#REF!,"Pending",'Redemption List'!P:P,"Not Yet") -> #REF!
Z40: =COUNTIFS('Redemption List'!K:K,Y40,#REF!,"Pending",'Redemption List'!P:P,"Not Yet") -> #REF!
...

Sheet Pending Details
B1: Id | C1: SL | D1: Email Communication by HighVoltage | E1: Voucher Delivery Status | F1: SLA (working days passed) | G1: Redemption Date & Time | H1: Employee ID | I1: Email | J1: Full name | K1: Reward Name | L1: BDT Value+ | M1: Selected Reward Option | N1: HVL Communication | O1: Voucher in proccess | P1: Delivery Status | Q1: Voucher Type | R1: Date ( For Late Deivery) | S1: Remarks | T1: @ | AD1: =COUNTIF($B:$B,B1) -> 1
B2: =IFERROR(__xludf.DUMMYFUNCTION("FILTER('Redemption List'!A:S,#REF!=""Pending"",'Redemption List'!P:P=""Not Yet"")"),"#N/A") -> #N/A | AD2: {=XLOOKUP(J2,Summery!G:G,Summery!H:H)} -> #NAME?

Sheet Employee Info
A1: =D1 -> Email | B1: ID | C1: Name | D1: Email | E1: Phone | G1: All-ID | H1: Name | I1: Email | J1: Phone
A2: =D2 -> mmaruf@square.org | B2: 1005 | C2: Mahiuddin Maruf | D2: mmaruf@square.org | E2: 1811310782 | G2: 1005 | H2: Mahiuddin Maruf | I2: mmaruf@square.org | J2: 1811310782
A3: =D3 -> zakhossain@square.org | B3: 10058 | C3: Md. Zakir Hossain | D3: zakhossain@square.org | E3: 1826662910 | G3: 10058 | H3: Md. Zakir Hossain | I3: zakhossain@square.org | J3: 1826662910
A4: =D4 -> jalam@square.org | B4: 10066 | C4: Md. Jane Alam | D4: jalam@square.org | E4: 1826662918 | G4: 10066 | H4: Md. Jane Alam | I4: jalam@square.org | J4: 1826662918
A5: =D5 -> trownok@square.org | B5: 1008 | C5: Tofazzal Rownok | D5: trownok@square.org | E5: 1811310915 | G5: 1008 | H5: Tofazzal Rownok | I5: trownok@square.org | J5: 1811310915
A6: =D6 -> aghani@square.org | B6: 10092 | C6: Abu Saleh Md. Osman Ghani | D6: aghani@square.org | E6: 1826662946 | G6: 10092 | H6: Abu Saleh Md. Osman Ghani | I6: aghani@square.org | J6: 1826662946
A7: =D7 -> mozmorshed@square.org | B7: 10107 | C7: Md. Mozahid Morshed | D7: mozmorshed@square.org | E7: 1826662960 | G7: 10107 | H7: Md. Mozahid Morshed | I7: mozmorshed@square.org | J7: 1826662960
A8: =D8 -> fsalehin@square.org | B8: 1011 | C8: Md. Al Ferdous Salehin | D8: fsalehin@square.org | E8: 1812311622 | G8: 1011 | H8: Md. Al Ferdous Salehin | I8: fsalehin@square.org | J8: 1812311622
A9: =D9 -> tmislam@square.org | B9: 10131 | C9: Talukder Mofidul Islam | D9: tmislam@square.org | E9: 1839900018 | G9: 10131 | H9: Talukder Mofidul Islam | I9: tmislam@square.org | J9: 1839900018
A10: =D10 -> arashal@square.org | B10: 1015 | C10: Manjurul Ahmed Rashal | D10: arashal@square.org | E10: 1812311633 | G10: 1015 | H10: Manjurul Ahmed Rashal | I10: arashal@square.org | J10: 1812311633
A11: =D11 -> faktar@square.org | B11: 10161 | C11: Farzana Aktar | D11: faktar@square.org | E11: 1839900048 | G11: 10161 | H11: Farzana Aktar | I11: faktar@square.org | J11: 1839900048
A12: =D12 -> snoman@square.org | B12: 10170 | C12: Md. Shahanur Noman | D12: snoman@square.org | E12: 1839900057 | G12: 10170 | H12: Md. Shahanur Noman | I12: snoman@square.org | J12: 1839900057
A13: =D13 -> juakter@square.org | B13: 10179 | C13: Juthy Akter | D13: juakter@square.org | E13: 1839900064 | G13: 10179 | H13: Juthy Akter | I13: juakter@square.org | J13: 1839900064
... A18: =D18 -> shafhasan@square.org | B18: 10295 | C18: Md. Shafinul Hasan | D18: shafhasan@square.org | E18: 1839900188 | G18: 10295 | H18: Md. Shafinul Hasan | I18: shafhasan@square.org | J18: 1839900188
A19: =D18 -> shafhasan@square.org | B19: 10311 | C19: Asher Ahmed Chowdhury | D19: ashchowdhury@square.org | E19: 1839900001 | G19: 10311 | H19: Asher Ahmed Chowdhury | I19: ashchowdhury@square.org | J19: 1839900001
A20: =D20 -> marahaman@square.org | B20: 10324 | C20: Md. Mahabur Rahaman | D20: marahaman@square.org | E20: 1839900223 | G20: 10324 | H20: Md. Mahabur Rahaman | I20: marahaman@square.org | J20: 1839900223
A21: =D21 -> mwrahaman@square.org | B21: 10325 | C21: Md. Wahidur Rahman | D21: mwrahaman@square.org | E21: 1839900224 | G21: 10325 | H21: Md. Wahidur Rahman | I21: mwrahaman@square.org | J21: 1839900224
A22: =D22 -> mmikbal@square.org | B22: 10330 | C22: Md. Maruf Ikbal | D22: mmikbal@square.org | E22: 1839900229 | G22: 10330 | H22: Md. Maruf Ikbal | I22: mmikbal@square.org | J22: 1839900229
A23: =D23 -> muakabir@square.org | B23: 10355 | C23: Mustofa Ahamed Kabir | D23: muakabir@square.org | E23: 1829988018 | G23: 10355 | H23: Mustofa Ahamed Kabir | I23: muakabir@square.org | J23: 1829988018
A24: =D24 -> ssisrar@square.org | B24: 10358 | C24: Syed Salahuddin Israr | D24: ssisrar@square.org | E24: 1839900255 | G24: 10358 | H24: Syed Salahuddin Israr | I24: ssisrar@square.org | J24: 1839900255
A25: =D25 -> rakarim@square.org | B25: 1036 | C25: Md. Rejaul Karim | D25: rakarim@square.org | E25: 1812311822 | G25: 1036 | H25: Md. Rejaul Karim | I25: rakarim@square.org | J25: 1812311822
A26: =D26 -> RMinhaz@square.org | B26: 10387 | C26: Rashed Minhaz | D26: RMinhaz@square.org | E26: 1839900284 | G26: 10387 | H26: Rashed Minhaz | I26: RMinhaz@square.org | J26: 1839900284
A27: =D27 -> skrislam@square.org | B27: 10394 | C27: Sk. Rakibul Islam | D27: skrislam@square.org | E27: 1839900291 | G27: 10394 | H27: Sk. Rakibul Islam | I27: skrislam@square.org | J27: 1839900291
A28: =D28 -> naislam@square.org | B28: 104 | C28: Md. Nazrul Islam | D28: naislam@square.org | E28: 1811810933 | G28: 104 | H28: Md. Nazrul Islam | I28: naislam@square.org | J28: 1811810933
A29: =D29 -> imiah@square.org | B29: 10498 | C29: Md. Ishaque Miah | D29: imiah@square.org | E29: 1839900451 | G29: 10498 | H29: Md. Ishaque Miah | I29: imiah@square.org | J29: 1839900451
A30: =D30 -> shafiqislam@square.org | B30: 10504 | C30: Mohammad Shafiqul Islam | D30: shafiqislam@square.org | E30: 1839900457 | G30: 10504 | H30: Mohammad Shafiqul Islam | I30: shafiqislam@square.org | J30: 1839900457
A31: =D31 -> AShayed@square.org | B31: 10621 | C31: A. F. M. Shayed | D31: AShayed@square.org | E31: 1839900606 | G31: 10621 | H31: A. F. M. Shayed | I31: AShayed@square.org | J31: 1839900606
... A118: =D118 -> sshanta@square.org | B118: 12187 | C118: Sayma Akter Shanta | D118: sshanta@square.org | E118: 1862401353 | G118: 12187 | H118: Sayma Akter Shanta | I118: sshanta@square.org | J118: 1862401353
A119: =D118 -> sshanta@square.org | B119: 12215 | C119: Md. Tanvir Hasnat | D119: mhasnat@square.org | E119: 1862401395 | G119: 12215 | H119: Md. Tanvir Hasnat | I119: mhasnat@square.org | J119: 1862401395
A120: =D120 -> iqahmed@square.org | B120: 1223 | C120: Iqbal Ahmed | D120: iqahmed@square.org | E120: 1814454041 | G120: 1223 | H120: Iqbal Ahmed | I120: iqahmed@square.org | J120: 1814454041
A121: =D121 -> zzerin@square.org | B121: 12235 | C121: Zebun Nessa Zerin | D121: zzerin@square.org | E121: 1862401416 | G121: 12235 | H121: Zebun Nessa Zerin | I121: zzerin@square.org | J121: 1862401416
A122: =D122 -> sshampa@square.org | B122: 12255 | C122: Shahana Khan Shampa | D122: sshampa@square.org | E122: 1862401434 | G122: 12255 | H122: Shahana Khan Shampa | I122: sshampa@square.org | J122: 1862401434
A123: =D123 -> mhassan@square.org | B123: 12292 | C123: Mahamudul Hassan | D123: mhassan@square.org | E123: 1862401473 | G123: 12292 | H123: Mahamudul Hassan | I123: mhassan@square.org | J123: 1862401473
A124: =D124 -> rgiasuddin@square.org | B124: 12294 | C124: Reza Mohammad Giasuddin | D124: rgiasuddin@square.org | E124: 1862401476 | G124: 12294 | H124: Reza Mohammad Giasuddin | I124: rgiasuddin@square.org | J124: 1862401476
A125: =D125 -> buddin@square.org | B125: 1230 | C125: Mohammad Belal Uddin | D125: buddin@square.org | E125: 1814452244 | G125: 1230 | H125: Mohammad Belal Uddin | I125: buddin@square.org | J125: 1814452244
A126: =D126 -> fahahmed@square.org | B126: 12307 | C126: Fahim Ahmed | D126: fahahmed@square.org | E126: 1862401489 | G126: 12307 | H126: Fahim Ahmed | I126: fahahmed@square.org | J126: 1862401489
A127: =D127 -> smahmood@square.org | B127: 12339 | C127: Sharif Mahmood | D127: smahmood@square.org | E127: 1862401520 | G127: 12339 | H127: Sharif Mahmood | I127: smahmood@square.org | J127: 1862401520
A128: =D128 -> mdhasan@square.org | B128: 12341 | C128: Md. Zahidul Hasan | D128: mdhasan@square.org | E128: 1862401522 | G128: 12341 | H128: Md. Zahidul Hasan | I128: mdhasan@square.org | J128: 1862401522
A129: =D129 -> alamgirhossain@square.org | B129: 12345 | C129: Alamgir Hossain | D129: alamgirhossain@square.org | E129: 1862401524 | G129: 12345 | H129: Alamgir Hossain | I129: alamgirhossain@square.org | J129: 1862401524
A130: =D130 -> dpramanik@square.org | B130: 1235 | C130: Md. Dulal Uddin Pramanik | D130: dpramanik@square.org | E130: 1814454043 | G130: 1235 | H130: Md. Dulal Uddin Pramanik | I130: dpramanik@square.org | J130: 1814454043
...

Sheet DB
A1: {=UNIQUE('Redemption List'!K:K)} -> #NAME? | B1: No of Redeem | C1: Complete | D1: ="Pending"&" "&SUM(D2:D20) -> Pending 0 | E1: ="BDT Value"&" "&SUM(E2:E20) -> BDT Value 0 | F1: ="BDT Value"&" "&SUM(F2:F20) -> BDT Value 0 | G1: =SUM(E2:E20)-SUM(F2:F20) -> 0
A2: #NAME? | B2: =COUNTIFS('Redemption List'!K:K,A2) -> 0 | C2: =COUNTIFS('Redemption List'!K:K,A2,'Redemption List'!P:P,$C$1) -> 0 | D2: =COUNTIFS('Redemption List'!K:K,A2,'Redemption List'!C:C,"") -> 0 | E2: =SUMIFS('Redemption List'!L:L,'Redemption List'!K:K,A2) -> 0 | F2: =SUMIFS('Redemption List'!L:L,'Redemption List'!P:P,"",'Redemption List'!K:K,A2) -> 0
A3: #NAME? | B3: =COUNTIFS('Redemption List'!K:K,A3) -> 0 | C3: =COUNTIFS('Redemption List'!K:K,A3,'Redemption List'!P:P,$C$1) -> 0 | D3: =COUNTIFS('Redemption List'!K:K,A3,'Redemption List'!C:C,"") -> 0 | E3: =SUMIFS('Redemption List'!L:L,'Redemption List'!K:K,A3) -> 0 | F3: =SUMIFS('Redemption List'!L:L,'Redemption List'!P:P,"",'Redemption List'!K:K,A3) -> 0
A4: #NAME? | B4: =COUNTIFS('Redemption List'!K:K,A4) -> 0 | C4: =COUNTIFS('Redemption List'!K:K,A4,'Redemption List'!P:P,$C$1) -> 0 | D4: =COUNTIFS('Redemption List'!K:K,A4,'Redemption List'!C:C,"") -> 0 | E4: =SUMIFS('Redemption List'!L:L,'Redemption List'!K:K,A4) -> 0 | F4: =SUMIFS('Redemption List'!L:L,'Redemption List'!P:P,"",'Redemption List'!K:K,A4) -> 0
A5: #NAME? | B5: =COUNTIFS('Redemption List'!K:K,A5) -> 0 | C5: =COUNTIFS('Redemption List'!K:K,A5,'Redemption List'!P:P,$C$1) -> 0 | D5: =COUNTIFS('Redemption List'!K:K,A5,'Redemption List'!C:C,"") -> 0 | E5: =SUMIFS('Redemption List'!L:L,'Redemption List'!K:K,A5) -> 0 | F5: =SUMIFS('Redemption List'!L:L,'Redemption List'!P:P,"",'Redemption List'!K:K,A5) -> 0
A6: #NAME? | B6: =COUNTIFS('Redemption List'!K:K,A6) -> 0 | C6: =COUNTIFS('Redemption List'!K:K,A6,'Redemption List'!P:P,$C$1) -> 0 | D6: =COUNTIFS('Redemption List'!K:K,A6,'Redemption List'!C:C,"") -> 0 | E6: =SUMIFS('Redemption List'!L:L,'Redemption List'!K:K,A6) -> 0 | F6: =SUMIFS('Redemption List'!L:L,'Redemption List'!P:P,"",'Redemption List'!K:K,A6) -> 0
A7: #NAME? | B7: =COUNTIFS('Redemption List'!K:K,A7) -> 0 | C7: =COUNTIFS('Redemption List'!K:K,A7,'Redemption List'!P:P,$C$1) -> 0 | D7: =COUNTIFS('Redemption List'!K:K,A7,'Redemption List'!C:C,"") -> 0 | E7: =SUMIFS('Redemption List'!L:L,'Redemption List'!K:K,A7) -> 0 | F7: =SUMIFS('Redemption List'!L:L,'Redemption List'!P:P,"",'Redemption List'!K:K,A7) -> 0
A8: #NAME? | B8: =COUNTIFS('Redemption List'!K:K,A8) -> 0 | C8: =COUNTIFS('Redemption List'!K:K,A8,'Redemption List'!P:P,$C$1) -> 0 | D8: =COUNTIFS('Redemption List'!K:K,A8,'Redemption List'!C:C,"") -> 0 | E8: =SUMIFS('Redemption List'!L:L,'Redemption List'!K:K,A8) -> 0 | F8: =SUMIFS('Redemption List'!L:L,'Redemption List'!P:P,"",'Redemption List'!K:K,A8) -> 0
A9: #NAME? | B9: =COUNTIFS('Redemption List'!K:K,A9) -> 0 | C9: =COUNTIFS('Redemption List'!K:K,A9,'Redemption List'!P:P,$C$1) -> 0 | D9: =COUNTIFS('Redemption List'!K:K,A9,'Redemption List'!C:C,"") -> 0 | E9: =SUMIFS('Redemption List'!L:L,'Redemption List'!K:K,A9) -> 0 | F9: =SUMIFS('Redemption List'!L:L,'Redemption List'!P:P,"",'Redemption List'!K:K,A9) -> 0
A10: #NAME? | B10: =COUNTIFS('Redemption List'!K:K,A10) -> 0 | C10: =COUNTIFS('Redemption List'!K:K,A10,'Redemption List'!P:P,$C$1) -> 0 | D10: =COUNTIFS('Redemption List'!K:K,A10,'Redemption List'!C:C,"") -> 0 | E10: =SUMIFS('Redemption List'!L:L,'Redemption List'!K:K,A10) -> 0 | F10: =SUMIFS('Redemption List'!L:L,'Redemption List'!P:P,"",'Redemption List'!K:K,A10) -> 0
A11: #NAME? | B11: =COUNTIFS('Redemption List'!K:K,A11) -> 0 | C11: =COUNTIFS('Redemption List'!K:K,A11,'Redemption List'!P:P,$C$1) -> 0 | D11: =COUNTIFS('Redemption List'!K:K,A11,'Redemption List'!C:C,"") -> 0 | E11: =SUMIFS('Redemption List'!L:L,'Redemption List'!K:K,A11) -> 0 | F11: =SUMIFS('Redemption List'!L:L,'Redemption List'!P:P,"",'Redemption List'!K:K,A11) -> 0
A12: #NAME? | B12: =COUNTIFS('Redemption List'!K:K,A12) -> 0 | C12: =COUNTIFS('Redemption List'!K:K,A12,'Redemption List'!P:P,$C$1) -> 0 | D12: =COUNTIFS('Redemption List'!K:K,A12,'Redemption List'!C:C,"") -> 0 | E12: =SUMIFS('Redemption List'!L:L,'Redemption List'!K:K,A12) -> 0 | F12: =SUMIFS('Redemption List'!L:L,'Redemption List'!P:P,"",'Redemption List'!K:K,A12) -> 0
A13: #NAME? | B13: =COUNTIFS('Redemption List'!K:K,A13) -> 0 | C13: =COUNTIFS('Redemption List'!K:K,A13,'Redemption List'!P:P,$C$1) -> 0 | D13: =COUNTIFS('Redemption List'!K:K,A13,'Redemption List'!C:C,"") -> 0 | E13: =SUMIFS('Redemption List'!L:L,'Redemption List'!K:K,A13) -> 0 | F13: =SUMIFS('Redemption List'!L:L,'Redemption List'!P:P,"",'Redemption List'!K:K,A13) -> 0
A14: #NAME? | B14: =COUNTIFS('Redemption List'!K:K,A14) -> 0 | C14: =COUNTIFS('Redemption List'!K:K,A14,'Redemption List'!P:P,$C$1) -> 0 | D14: =COUNTIFS('Redemption List'!K:K,A14,'Redemption List'!C:C,"") -> 0 | E14: =SUMIFS('Redemption List'!L:L,'Redemption List'!K:K,A14) -> 0 | F14: =SUMIFS('Redemption List'!L:L,'Redemption List'!P:P,"",'Redemption List'!K:K,A14) -> 0
B15: =COUNTIFS('Redemption List'!K:K,A15) -> 0 | C15: =COUNTIFS('Redemption List'!K:K,A15,'Redemption List'!P:P,$C$1) -> 0 | D15: =COUNTIFS('Redemption List'!K:K,A15,'Redemption List'!C:C,"") -> 0 | E15: =SUMIFS('Redemption List'!L:L,'Redemption List'!K:K,A15) -> 0 | F15: =SUMIFS('Redemption List'!L:L,'Redemption List'!P:P,"",'Redemption List'!K:K,A15) -> 0
B16: =COUNTIFS('Redemption List'!K:K,A16) -> 0 | C16: =COUNTIFS('Redemption List'!K:K,A16,'Redemption List'!P:P,$C$1) -> 0 | D16: =COUNTIFS('Redemption List'!K:K,A16,'Redemption List'!C:C,"") -> 0 | E16: =SUMIFS('Redemption List'!L:L,'Redemption List'!K:K,A16) -> 0 | F16: =SUMIFS('Redemption List'!L:L,'Redemption List'!P:P,"",'Redemption List'!K:K,A16) -> 0
B17: =COUNTIFS('Redemption List'!K:K,A17) -> 0 | C17: =COUNTIFS('Redemption List'!K:K,A17,'Redemption List'!P:P,$C$1) -> 0 | D17: =COUNTIFS('Redemption List'!K:K,A17,'Redemption List'!C:C,"") -> 0 | E17: =SUMIFS('Redemption List'!L:L,'Redemption List'!K:K,A17) -> 0 | F17: =SUMIFS('Redemption List'!L:L,'Redemption List'!P:P,"",'Redemption List'!K:K,A17) -> 0
B18: =COUNTIFS('Redemption List'!K:K,A18) -> 0 | C18: =COUNTIFS('Redemption List'!K:K,A18,'Redemption List'!P:P,$C$1) -> 0 | D18: =COUNTIFS('Redemption List'!K:K,A18,'Redemption List'!C:C,"") -> 0 | E18: =SUMIFS('Redemption List'!L:L,'Redemption List'!K:K,A18) -> 0 | F18: =SUMIFS('Redemption List'!L:L,'Redemption List'!P:P,"",'Redemption List'!K:K,A18) -> 0
B19: =COUNTIFS('Redemption List'!K:K,A19) -> 0 | C19: =COUNTIFS('Redemption List'!K:K,A19,'Redemption List'!P:P,$C$1) -> 0 | D19: =COUNTIFS('Redemption List'!K:K,A19,'Redemption List'!C:C,"") -> 0 | E19: =SUMIFS('Redemption List'!L:L,'Redemption List'!K:K,A19) -> 0 | F19: =SUMIFS('Redemption List'!L:L,'Redemption List'!P:P,"",'Redemption List'!K:K,A19) -> 0
B20: =COUNTIFS('Redemption List'!K:K,A20) -> 0 | C20: =COUNTIFS('Redemption List'!K:K,A20,'Redemption List'!P:P,$C$1) -> 0 | D20: =COUNTIFS('Redemption List'!K:K,A20,'Redemption List'!C:C,"") -> 0 | E20: =SUMIFS('Redemption List'!L:L,'Redemption List'!K:K,A20) -> 0 | F20: =SUMIFS('Redemption List'!L:L,'Redemption List'!P:P,"",'Redemption List'!K:K,A20) -> 0
